I'm sorry, but an uncaught exception occurred.

While running game code:
  File "game/talk_to_adam.rpy", line 13, in script
    python:
  File "game/talk_to_adam.rpy", line 17, in <module>
    resp = query_inworld_api("adam", question, protagonist_name)
  File "game/intro.rpy", line 31, in query_inworld_api
    print(x['lalal'])
KeyError: 'lalal'

-- Full Traceback ------------------------------------------------------------

Full traceback:
  File "game/talk_to_adam.rpy", line 13, in script
    python:
  File "/home/kyatt/Desktop/uczelnia/magisterskie/masters-backup/renpy-8.2.0-sdk/renpy/ast.py", line 823, in execute
    renpy.python.py_exec_bytecode(self.code.bytecode, self.hide, store=self.store)
  File "/home/kyatt/Desktop/uczelnia/magisterskie/masters-backup/renpy-8.2.0-sdk/renpy/python.py", line 1178, in py_exec_bytecode
    exec(bytecode, globals, locals)
  File "game/talk_to_adam.rpy", line 17, in <module>
    resp = query_inworld_api("adam", question, protagonist_name)
  File "game/intro.rpy", line 31, in query_inworld_api
    print(x['lalal'])
KeyError: 'lalal'

Linux-6.5.0-17-generic-x86_64-with-glibc2.35 x86_64
Ren'Py 8.2.0.24012702
GameAI 1.0
Fri Feb 16 00:38:17 2024
