I'm sorry, but an uncaught exception occurred.

While running game code:
  File "game/talk_to_adam.rpy", line 14, in script
    python:
  File "game/talk_to_adam.rpy", line 15, in <module>
    prompt = "{size=10}Remaining questions: {}. \nExample questions: 'Where were you?', 'What do you know about X?', \nType 'exit' to quit.{/size}".format(
KeyError: 'size=10'

-- Full Traceback ------------------------------------------------------------

Full traceback:
  File "game/talk_to_adam.rpy", line 14, in script
    python:
  File "F:\uczelnia\magister\PRACA DYPLOMOWA\renpy-8.2.0-sdk\renpy\ast.py", line 823, in execute
    renpy.python.py_exec_bytecode(self.code.bytecode, self.hide, store=self.store)
  File "F:\uczelnia\magister\PRACA DYPLOMOWA\renpy-8.2.0-sdk\renpy\python.py", line 1178, in py_exec_bytecode
    exec(bytecode, globals, locals)
  File "game/talk_to_adam.rpy", line 15, in <module>
    prompt = "{size=10}Remaining questions: {}. \nExample questions: 'Where were you?', 'What do you know about X?', \nType 'exit' to quit.{/size}".format(
KeyError: 'size=10'

Windows-10-10.0.19044 AMD64
Ren'Py 8.2.0.24012702
GameAI 1.0
Wed May  1 00:52:23 2024
